Workbook

Sheet Raw_Data
A1: Order_ID | B1: Customer_ID | C1: Order_Date | D1: Product_ID | E1: Quantity | F1: Unit_Price | G1: Total_Revenue | H1: Country | I1: Status
A2: 1001 | B2: C001 | C2: 2024-02-07 | D2: P05 | E2: 3 | F2: 9325 | G2: 27975 | H2: India | I2: Completed
A3: 1002 | B3: C002 | C3: 2024-02-03 | D3: P07 | E3: 4 | F3: 5029 | G3: 20116 | H3: Canada | I3: Cancelled
A4: 1003 | B4: C003 | C4: 2024-01-07 | D4: P15 | E4: 3 | F4: 2919 | G4: 8757 | H4: USA | I4: Cancelled
A5: 1004 | B5: C004 | C5: 2024-01-10 | D5: P09 | E5: 3 | F5: 6250 | G5: 18750 | H5: UK | I5: Cancelled
A6: 1005 | B6: C005 | C6: 2024-02-04 | D6: P13 | E6: 3 | F6: 895 | G6: 2685 | H6: USA | I6: Completed
A7: 1006 | B7: C006 | C7: 2024-02-08 | D7: P04 | E7: 1 | F7: 9361 | G7: 9361 | H7: USA | I7: Cancelled
A8: 1007 | B8: C007 | C8: 2024-01-27 | D8: P10 | E8: 1 | F8: 2619 | G8: 2619 | H8: India | I8: Completed
A9: 1008 | B9: C008 | C9: 2024-01-02 | D9: P13 | E9: 4 | F9: 1067 | G9: 4268 | H9: USA | I9: Cancelled
A10: 1009 | B10: C009 | C10: 2024-01-27 | D10: P12 | E10: 3 | F10: 8351 | G10: 25053 | H10: India | I10: Cancelled
A11: 1010 | B11: C010 | C11: 2024-01-12 | D11: P07 | E11: 5 | F11: 1265 | G11: 6325 | H11: Canada | I11: Completed
A12: 1006 | B12: C011 | C12: 2024-01-31 | D12: P11 | E12: 5 | F12: 3635 | G12: 18175 | H12: Canada | I12: Cancelled
A13: 1012 | B13: C012 | C13: 2024-02-10 | D13: P10 | E13: 4 | F13: 9598 | G13: 38392 | H13: India | I13: Cancelled
... A121: 1120 | B121: C120 | C121: 2024-01-07 | D121: P02 | E121: 5 | F121: 6867 | G121: 34335 | H121: USA | I121: Cancelled
A122: 1121 | B122: C121 | D122: P04 | E122: 5 | F122: 8891 | G122: 44455 | H122: Canada | I122: Cancelled
A123: 1122 | B123: C122 | C123: 2024-01-27 | D123: P07 | E123: 4 | F123: 7463 | G123: 29852 | H123: USA | I123: Cancelled
A124: 1123 | B124: C123 | C124: 2024-01-23 | D124: P11 | E124: 1 | F124: 1243 | G124: 1243 | H124: Canada | I124: Cancelled
A125: 1124 | B125: C124 | C125: 2024-01-16 | D125: P02 | E125: 4 | F125: 3680 | G125: 14720 | H125: India | I125: Pending
A126: 1125 | B126: C125 | C126: 2024-01-30 | D126: P03 | E126: 3 | F126: 3270 | G126: 9810 | H126: India | I126: Cancelled
A127: 1126 | B127: C126 | C127: 2024-02-13 | D127: P05 | E127: 2 | F127: 8303 | G127: 16606 | H127: Canada | I127: Completed
A128: 1127 | B128: C127 | C128: 2024-02-21 | D128: P02 | E128: 3 | F128: 2858 | G128: 8574 | H128: UK | I128: Completed
A129: 1128 | B129: C128 | C129: 2024-01-10 | D129: P02 | E129: 3 | F129: 3620 | G129: 10860 | H129: UK | I129: Cancelled
A130: 1129 | B130: C129 | C130: 2024-01-19 | D130: P11 | E130: 3 | F130: 922 | G130: 2766 | H130: UK | I130: Pending
A131: 1130 | B131: C130 | C131: 2024-02-28 | D131: P15 | E131: 3 | F131: 6586 | G131: 19758 | H131: India | I131: Cancelled
A132: 1131 | B132: C131 | C132: 2024-01-19 | D132: P09 | E132: 5 | F132: 7281 | G132: 36405 | H132: india | I132: Cancelled
A133: 1132 | B133: C132 | C133: 2024-01-03 | D133: P11 | E133: 5 | F133: 9219 | G133: 46095 | H133: USA | I133: Completed
A134: 1133 | B134: C133 | C134: 2024-02-15 | D134: P02 | E134: 3 | F134: 5114 | G134: 15342 | H134: Canada | I134: Cancelled
... A151: 1150 | B151: C150 | C151: 2024-02-23 | D151: P09 | E151: 5 | F151: 1325 | G151: 6625 | H151: Canada | I151: Cancelled
A152: 1151 | B152: C151 | C152: 2024-02-05 | D152: P10 | E152: 1 | G152: 1522 | H152: Canada | I152: Cancelled
A153: 1152 | B153: C152 | C153: 2024-01-25 | D153: P12 | E153: 5 | F153: 4582 | G153: 22910 | H153: Canada | I153: Completed
A154: 1153 | B154: C153 | C154: 2024-01-27 | D154: P15 | E154: 4 | F154: 2295 | G154: 9180 | H154: India | I154: Cancelled
A155: 1154 | B155: C154 | C155: 2024-02-18 | D155: P06 | E155: 2 | F155: 1407 | G155: 2814 | H155: UK | I155: Pending
A156: 1155 | B156: C155 | C156: 2024-01-11 | D156: P02 | E156: 5 | F156: 9213 | G156: 46065 | H156: Canada | I156: Pending
A157: 1156 | B157: C156 | C157: 2024-03-01 | D157: P01 | E157: 3 | F157: 619 | G157: 1857 | H157: India | I157: Cancelled
A158: 1157 | B158: C157 | C158: 2024-01-06 | D158: P02 | E158: 1 | F158: 3532 | G158: 3532 | H158: USA | I158: Completed
A159: 1158 | B159: C158 | C159: 2024-01-05 | D159: P07 | E159: 1 | F159: 1609 | G159: 1609 | H159: UK | I159: Cancelled
A160: 1159 | B160: C159 | C160: 2024-02-02 | D160: P13 | E160: 1 | F160: 8664 | G160: 8664 | H160: India | I160: Cancelled
A161: 1160 | B161: C160 | C161: 2024-02-15 | D161: P01 | E161: 1 | F161: 3268 | G161: 3268 | H161: Canada | I161: Completed
A162: 1161 | B162: C161 | C162: 2024-02-23 | D162: P13 | E162: 3 | G162: 12132 | H162: USA | I162: Completed
A163: 1162 | B163: C162 | C163: 2024-01-16 | D163: P06 | E163: 2 | F163: 4672 | G163: 9344 | H163: India | I163: Pending
...

Sheet Tasks
A1: Tasks | B1: Issue | C1: Impact | D1: Recommendation | E1: Action Taken
A2: 1. Identify duplicate Order_ID records. | B2: Order_ID 1006 and 1016 appears in multiple records with conflicting transaction details (different customer, date, quantity, and country). | C2: This compromises transaction uniqueness and may result in incorrect revenue aggregation and reporting inconsistencies. | D2: Investigate source system for ID reuse or data merge errors and enforce uniqueness constraint on Order_ID. | E2: Identified duplicate IDs and flagged affected records.
A3: 2. Identify revenue mismatches (Total_Revenue != Quantity * Unit_Price). | B3: 6 records where Total_Revenue does not equal Quantity × Unit_Price. | C3: Leads to incorrect financial reporting and revenue misstatement. | D3: Recalculate revenue using standardized formula and validate mismatched transactions against source data. | E3: Recalculated revenue and flagged mismatched entries.
A4: 3. Identify negative Quantity values. | B4: Negative Quantity values detected in 2 records. | C4: Leads to incorrect product sales reporting and revenue misstatement | D4: Validate whether negative quantities represent legitimate returns/cancellations. I f not permitted by business rules, enforce positive-only quantity validation. | E4: Filtered and quantified negative quantity records.
A5: 4. Detect missing values across all columns. | B5: 3 records are detected with missing value 1 order date and 2 Unit Price | C5: Leads to Revenue misstatement, sales and finance reporting | D5: Validate missing fields against source records and implement mandatory field checks to prevent null values in critical columns. | E5: Detected and documented records with missing critical fields.
A6: 5. Identify invalid Order_Date entries. | B6: Order_Date column contains values stored as text instead of proper date format (249 records affected). | C6: May cause errors in date-based filtering, grouping, and time-series analysis. | D6: Standardize Order_Date to valid date format during ingestion and enforce strict date validation controls. | E6: Validated date format and identified text-based entries.
A7: 6. Standardize inconsistent Country values. | B7: Country column contained inconsistent representations (e.g., "india", "U.S.A", "Uk", trailing spaces). | C7: Causes fragmented aggregation in country-level analysis and inaccurate reporting. | D7: Implement dropdown validation or reference mapping during data entry to prevent inconsistent country inputs. | E7: Standardized country values using TRIM and controlled mapping logic to ensure uniform formatting.
A8: 7. Validate Status column (Allowed: Completed, Pending, Cancelled). | B8: Status column contains values outside the allowed set (e.g., "Done", "Processing"). | C8: May cause incorrect status-based reporting and workflow misclassification. | D8: Restrict Status column using dropdown validation limited to Completed, Pending, and Cancelled. | E8: Validated Status against allowed values and flagged exceptions.
A9: 8. Validate Product_ID using lookup against Product_Master. | B9: 2 records contain Product_ID values not found in the Product_Master reference table. | C9: These records may result in incorrect product-level reporting, revenue misclassification, and broken referential integrity between transactional and master data. | D9: Enforce referential integrity by validating Product_ID against the master reference during data ingestion and restrict entry to approved product list. | E9: Validated Product_ID values using lookup against Product_Master and flagged unmatched entries.
A10: 9. Count total UNIQUE problematic rows (avoid double counting). | B10: 10 unique rows were identified with at least one data quality issue (including revenue mismatch, duplicate Order_ID, invalid Product_ID, missing values, or invalid date). | C10: These inconsistencies may lead to inaccurate revenue reporting, duplicate transaction counting, incorrect product-level aggregation, and unreliable sales and financial reporting. | D10: Perform validation against source systems to correct erroneous records before reporting. Implement automated data validation rules at ingestion stage to prevent duplicate entries, invalid references, and incomplete records from entering the dataset. | E10: Validated Status against allowed values and flagged exceptions.
A11: 10. Calculate overall row-level error rate. | B11: Total Rows Analyzed: 250, Unique Problematic Rows: 10, Overall Row-Level Error Rate: 4% | C11: Approximately 4% of transactions contain at least one data quality issue, which may affect revenue reporting, product aggregation, and financial accuracy. | D11: Implement automated validation controls during data ingestion to reduce transaction-level errors and strengthen data integrity. | E11: Calculated error rate using problematic rows over total records.
A12: 11. Calculate column-level error rate for Quantity. | B12: 2 records contain invalid Quantity values (negative entries). Column-Level Error Rate (Quantity): 0.8% | C12: May distort product sales volume and revenue calculations if not aligned with business rules. | D12: Validate whether negative quantities represent legitimate returns. If not, enforce positive-only quantity validation at data entry. | E12: Computed column-level error rate for Quantity.
... A14: 13. Create Pivot Table: Orders by Status. | B14: Order status distribution was not summarized, making it difficult to assess operational pipeline health. | C14: Without status aggregation, invalid status values (Done, Processing) remain hidden and unquantified in reporting. | D14: Create a Pivot Table summarizing Order Count by Status to identify valid vs invalid status entries. | E14: Created Pivot summarizing order count by status.

Sheet Cleaned_Data
A1: Order_ID | B1: Customer_ID | C1: Order_Date | D1: Product_ID | E1: Quantity | F1: Unit_Price | G1: Total_Revenue | H1: Country | I1: Status | J1: Revenue_Check | K1: Date_Check | L1: Country_Validation | M1: Order_Validation | N1: Product_Validation2 | O1: Row_Issues
A2: 1001 | B2: C001 | C2: 2024-02-07 | D2: P05 | E2: 3 | F2: 9325 | G2: 27975 | H2: India | I2: Completed | J2: =IF(G2<>(E2*F2), "Mismatch", "Ok") -> Ok | K2: =ISNUMBER(C2) -> FALSE | L2: =_xlfn.XLOOKUP( UPPER(SUBSTITUTE(TRIM(H2),".","")), A:A, B:B, UPPER(SUBSTITUTE(TRIM(H2),".","")) ) -> INDIA | M2: =IF(OR(I2="Completed", I2="Pending", I2="Cancelled"), "Valid", "Invalid") -> Valid | N2: =_xlfn.XLOOKUP(D2, Product_Master!A:A, Product_Master!A:A, "Invalid") -> P05 | O2: =IF(OR(J2="Mismatch", K2="False", M2="Invalid", N2="Invalid"), "Problem", "Clean") -> Clean
A3: 1002 | B3: C002 | C3: 2024-02-03 | D3: P07 | E3: 4 | F3: 5029 | G3: 20116 | H3: Canada | I3: Cancelled | J3: =IF(G3<>(E3*F3), "Mismatch", "Ok") -> Ok | K3: =ISNUMBER(C3) -> FALSE | L3: =_xlfn.XLOOKUP( UPPER(SUBSTITUTE(TRIM(H3),".","")), A:A, B:B, UPPER(SUBSTITUTE(TRIM(H3),".","")) ) -> CANADA | M3: =IF(OR(I3="Completed", I3="Pending", I3="Cancelled"), "Valid", "Invalid") -> Valid | N3: =_xlfn.XLOOKUP(D3, Product_Master!A:A, Product_Master!A:A, "Invalid") -> P07 | O3: =IF(OR(J3="Mismatch", K3="False", M3="Invalid", N3="Invalid"), "Problem", "Clean") -> Clean
A4: 1003 | B4: C003 | C4: 2024-01-07 | D4: P15 | E4: 3 | F4: 2919 | G4: 8757 | H4: USA | I4: Cancelled | J4: =IF(G4<>(E4*F4), "Mismatch", "Ok") -> Ok | K4: =ISNUMBER(C4) -> FALSE | L4: =_xlfn.XLOOKUP( UPPER(SUBSTITUTE(TRIM(H4),".","")), A:A, B:B, UPPER(SUBSTITUTE(TRIM(H4),".","")) ) -> USA | M4: =IF(OR(I4="Completed", I4="Pending", I4="Cancelled"), "Valid", "Invalid") -> Valid | N4: =_xlfn.XLOOKUP(D4, Product_Master!A:A, Product_Master!A:A, "Invalid") -> P15 | O4: =IF(OR(J4="Mismatch", K4="False", M4="Invalid", N4="Invalid"), "Problem", "Clean") -> Clean
A5: 1004 | B5: C004 | C5: 2024-01-10 | D5: P09 | E5: 3 | F5: 6250 | G5: 18750 | H5: UK | I5: Cancelled | J5: =IF(G5<>(E5*F5), "Mismatch", "Ok") -> Ok | K5: =ISNUMBER(C5) -> FALSE | L5: =_xlfn.XLOOKUP( UPPER(SUBSTITUTE(TRIM(H5),".","")), A:A, B:B, UPPER(SUBSTITUTE(TRIM(H5),".","")) ) -> UK | M5: =IF(OR(I5="Completed", I5="Pending", I5="Cancelled"), "Valid", "Invalid") -> Valid | N5: =_xlfn.XLOOKUP(D5, Product_Master!A:A, Product_Master!A:A, "Invalid") -> P09 | O5: =IF(OR(J5="Mismatch", K5="False", M5="Invalid", N5="Invalid"), "Problem", "Clean") -> Clean
A6: 1005 | B6: C005 | C6: 45326 | D6: P13 | E6: 3 | F6: 895 | G6: 2685 | H6: USA | I6: Completed | J6: =IF(G6<>(E6*F6), "Mismatch", "Ok") -> Ok | K6: =ISNUMBER(C6) -> TRUE | L6: =_xlfn.XLOOKUP( UPPER(SUBSTITUTE(TRIM(H6),".","")), A:A, B:B, UPPER(SUBSTITUTE(TRIM(H6),".","")) ) -> USA | M6: =IF(OR(I6="Completed", I6="Pending", I6="Cancelled"), "Valid", "Invalid") -> Valid | N6: =_xlfn.XLOOKUP(D6, Product_Master!A:A, Product_Master!A:A, "Invalid") -> P13 | O6: =IF(OR(J6="Mismatch", K6="False", M6="Invalid", N6="Invalid"), "Problem", "Clean") -> Clean
A7: 1006 | B7: C006 | C7: 2024-02-08 | D7: P04 | E7: 1 | F7: 9361 | G7: 9361 | H7: USA | I7: Cancelled | J7: =IF(G7<>(E7*F7), "Mismatch", "Ok") -> Ok | K7: =ISNUMBER(C7) -> FALSE | L7: =_xlfn.XLOOKUP( UPPER(SUBSTITUTE(TRIM(H7),".","")), A:A, B:B, UPPER(SUBSTITUTE(TRIM(H7),".","")) ) -> USA | M7: =IF(OR(I7="Completed", I7="Pending", I7="Cancelled"), "Valid", "Invalid") -> Valid | N7: =_xlfn.XLOOKUP(D7, Product_Master!A:A, Product_Master!A:A, "Invalid") -> P04 | O7: =IF(OR(J7="Mismatch", K7="False", M7="Invalid", N7="Invalid"), "Problem", "Clean") -> Clean
A8: 1007 | B8: C007 | C8: 2024-01-27 | D8: P10 | E8: 1 | F8: 2619 | G8: 2619 | H8: India | I8: Completed | J8: =IF(G8<>(E8*F8), "Mismatch", "Ok") -> Ok | K8: =ISNUMBER(C8) -> FALSE | L8: =_xlfn.XLOOKUP( UPPER(SUBSTITUTE(TRIM(H8),".","")), A:A, B:B, UPPER(SUBSTITUTE(TRIM(H8),".","")) ) -> INDIA | M8: =IF(OR(I8="Completed", I8="Pending", I8="Cancelled"), "Valid", "Invalid") -> Valid | N8: =_xlfn.XLOOKUP(D8, Product_Master!A:A, Product_Master!A:A, "Invalid") -> P10 | O8: =IF(OR(J8="Mismatch", K8="False", M8="Invalid", N8="Invalid"), "Problem", "Clean") -> Clean
A9: 1008 | B9: C008 | C9: 2024-01-02 | D9: P13 | E9: 4 | F9: 1067 | G9: 4268 | H9: USA | I9: Cancelled | J9: =IF(G9<>(E9*F9), "Mismatch", "Ok") -> Ok | K9: =ISNUMBER(C9) -> FALSE | L9: =_xlfn.XLOOKUP( UPPER(SUBSTITUTE(TRIM(H9),".","")), A:A, B:B, UPPER(SUBSTITUTE(TRIM(H9),".","")) ) -> USA | M9: =IF(OR(I9="Completed", I9="Pending", I9="Cancelled"), "Valid", "Invalid") -> Valid | N9: =_xlfn.XLOOKUP(D9, Product_Master!A:A, Product_Master!A:A, "Invalid") -> P13 | O9: =IF(OR(J9="Mismatch", K9="False", M9="Invalid", N9="Invalid"), "Problem", "Clean") -> Clean
A10: 1009 | B10: C009 | C10: 2024-01-27 | D10: P12 | E10: 3 | F10: 8351 | G10: 25053 | H10: India | I10: Cancelled | J10: =IF(G10<>(E10*F10), "Mismatch", "Ok") -> Ok | K10: =ISNUMBER(C10) -> FALSE | L10: =_xlfn.XLOOKUP( UPPER(SUBSTITUTE(TRIM(H10),".","")), A:A, B:B, UPPER(SUBSTITUTE(TRIM(H10),".","")) ) -> INDIA | M10: =IF(OR(I10="Completed", I10="Pending", I10="Cancelled"), "Valid", "Invalid") -> Valid | N10: =_xlfn.XLOOKUP(D10, Product_Master!A:A, Product_Master!A:A, "Invalid") -> P12 | O10: =IF(OR(J10="Mismatch", K10="False", M10="Invalid", N10="Invalid"), "Problem", "Clean") -> Clean
A11: 1010 | B11: C010 | C11: 2024-01-12 | D11: P07 | E11: 5 | F11: 1265 | G11: 6325 | H11: Canada | I11: Completed | J11: =IF(G11<>(E11*F11), "Mismatch", "Ok") -> Ok | K11: =ISNUMBER(C11) -> FALSE | L11: =_xlfn.XLOOKUP( UPPER(SUBSTITUTE(TRIM(H11),".","")), A:A, B:B, UPPER(SUBSTITUTE(TRIM(H11),".","")) ) -> CANADA | M11: =IF(OR(I11="Completed", I11="Pending", I11="Cancelled"), "Valid", "Invalid") -> Valid | N11: =_xlfn.XLOOKUP(D11, Product_Master!A:A, Product_Master!A:A, "Invalid") -> P07 | O11: =IF(OR(J11="Mismatch", K11="False", M11="Invalid", N11="Invalid"), "Problem", "Clean") -> Clean
A12: 1006 | B12: C011 | C12: 2024-01-31 | D12: P11 | E12: 5 | F12: 3635 | G12: 18175 | H12: Canada | I12: Cancelled | J12: =IF(G12<>(E12*F12), "Mismatch", "Ok") -> Ok | K12: =ISNUMBER(C12) -> FALSE | L12: =_xlfn.XLOOKUP( UPPER(SUBSTITUTE(TRIM(H12),".","")), A:A, B:B, UPPER(SUBSTITUTE(TRIM(H12),".","")) ) -> CANADA | M12: =IF(OR(I12="Completed", I12="Pending", I12="Cancelled"), "Valid", "Invalid") -> Valid | N12: =_xlfn.XLOOKUP(D12, Product_Master!A:A, Product_Master!A:A, "Invalid") -> P11 | O12: =IF(OR(J12="Mismatch", K12="False", M12="Invalid", N12="Invalid"), "Problem", "Clean") -> Clean
A13: 1012 | B13: C012 | C13: 2024-02-10 | D13: P10 | E13: 4 | F13: 9598 | G13: 38392 | H13: India | I13: Cancelled | J13: =IF(G13<>(E13*F13), "Mismatch", "Ok") -> Ok | K13: =ISNUMBER(C13) -> FALSE | L13: =_xlfn.XLOOKUP( UPPER(SUBSTITUTE(TRIM(H13),".","")), A:A, B:B, UPPER(SUBSTITUTE(TRIM(H13),".","")) ) -> INDIA | M13: =IF(OR(I13="Completed", I13="Pending", I13="Cancelled"), "Valid", "Invalid") -> Valid | N13: =_xlfn.XLOOKUP(D13, Product_Master!A:A, Product_Master!A:A, "Invalid") -> P10 | O13: =IF(OR(J13="Mismatch", K13="False", M13="Invalid", N13="Invalid"), "Problem", "Clean") -> Clean
A14: 1013 | B14: C013 | C14: 2024-01-28 | D14: P13 | E14: 2 | F14: 849 | G14: 1698 | H14: USA | I14: Cancelled | J14: =IF(G14<>(E14*F14), "Mismatch", "Ok") -> Ok | K14: =ISNUMBER(C14) -> FALSE | L14: =_xlfn.XLOOKUP( UPPER(SUBSTITUTE(TRIM(H14),".","")), A:A, B:B, UPPER(SUBSTITUTE(TRIM(H14),".","")) ) -> USA | M14: =IF(OR(I14="Completed", I14="Pending", I14="Cancelled"), "Valid", "Invalid") -> Valid | N14: =_xlfn.XLOOKUP(D14, Product_Master!A:A, Product_Master!A:A, "Invalid") -> P13 | O14: =IF(OR(J14="Mismatch", K14="False", M14="Invalid", N14="Invalid"), "Problem", "Clean") -> Clean
A15: 1014 | B15: C014 | C15: 2024-01-20 | D15: P01 | E15: 1 | F15: 9757 | G15: 9757 | H15: India | I15: Cancelled | J15: =IF(G15<>(E15*F15), "Mismatch", "Ok") -> Ok | K15: =ISNUMBER(C15) -> FALSE | L15: =_xlfn.XLOOKUP( UPPER(SUBSTITUTE(TRIM(H15),".","")), A:A, B:B, UPPER(SUBSTITUTE(TRIM(H15),".","")) ) -> INDIA | M15: =IF(OR(I15="Completed", I15="Pending", I15="Cancelled"), "Valid", "Invalid") -> Valid | N15: =_xlfn.XLOOKUP(D15, Product_Master!A:A, Product_Master!A:A, "Invalid") -> P01 | O15: =IF(OR(J15="Mismatch", K15="False", M15="Invalid", N15="Invalid"), "Problem", "Clean") -> Clean
A16: 1015 | B16: C015 | C16: 2024-01-28 | D16: P07 | E16: 1 | F16: 5954 | G16: 5954 | H16: USA | I16: Cancelled | J16: =IF(G16<>(E16*F16), "Mismatch", "Ok") -> Ok | K16: =ISNUMBER(C16) -> FALSE | L16: =_xlfn.XLOOKUP( UPPER(SUBSTITUTE(TRIM(H16),".","")), A:A, B:B, UPPER(SUBSTITUTE(TRIM(H16),".","")) ) -> USA | M16: =IF(OR(I16="Completed", I16="Pending", I16="Cancelled"), "Valid", "Invalid") -> Valid | N16: =_xlfn.XLOOKUP(D16, Product_Master!A:A, Product_Master!A:A, "Invalid") -> P07 | O16: =IF(OR(J16="Mismatch", K16="False", M16="Invalid", N16="Invalid"), "Problem", "Clean") -> Clean
A17: 1016 | B17: C016 | C17: 2024-01-19 | D17: P07 | E17: 3 | F17: 7346 | G17: 22038 | H17: USA | I17: Pending | J17: =IF(G17<>(E17*F17), "Mismatch", "Ok") -> Ok | K17: =ISNUMBER(C17) -> FALSE | L17: =_xlfn.XLOOKUP( UPPER(SUBSTITUTE(TRIM(H17),".","")), A:A, B:B, UPPER(SUBSTITUTE(TRIM(H17),".","")) ) -> USA | M17: =IF(OR(I17="Completed", I17="Pending", I17="Cancelled"), "Valid", "Invalid") -> Valid | N17: =_xlfn.XLOOKUP(D17, Product_Master!A:A, Product_Master!A:A, "Invalid") -> P07 | O17: =IF(OR(J17="Mismatch", K17="False", M17="Invalid", N17="Invalid"), "Problem", "Clean") -> Clean
A18: 1017 | B18: C017 | C18: 2024-01-28 | D18: P11 | E18: 5 | F18: 9189 | G18: 45945 | H18: India | I18: Cancelled | J18: =IF(G18<>(E18*F18), "Mismatch", "Ok") -> Ok | K18: =ISNUMBER(C18) -> FALSE | L18: =_xlfn.XLOOKUP( UPPER(SUBSTITUTE(TRIM(H18),".","")), A:A, B:B, UPPER(SUBSTITUTE(TRIM(H18),".","")) ) -> INDIA | M18: =IF(OR(I18="Completed", I18="Pending", I18="Cancelled"), "Valid", "Invalid") -> Valid | N18: =_xlfn.XLOOKUP(D18, Product_Master!A:A, Product_Master!A:A, "Invalid") -> P11 | O18: =IF(OR(J18="Mismatch", K18="False", M18="Invalid", N18="Invalid"), "Problem", "Clean") -> Clean
... A121: 1120 | B121: C120 | C121: 2024-01-07 | D121: P02 | E121: 5 | F121: 6867 | G121: 34335 | H121: USA | I121: Cancelled | J121: =IF(G121<>(E121*F121), "Mismatch", "Ok") -> Ok | K121: =ISNUMBER(C121) -> FALSE | L121: =_xlfn.XLOOKUP( UPPER(SUBSTITUTE(TRIM(H121),".","")), A:A, B:B, UPPER(SUBSTITUTE(TRIM(H121),".","")) ) -> USA | M121: =IF(OR(I121="Completed", I121="Pending", I121="Cancelled"), "Valid", "Invalid") -> Valid | N121: =_xlfn.XLOOKUP(D121, Product_Master!A:A, Product_Master!A:A, "Invalid") -> P02 | O121: =IF(OR(J121="Mismatch", K121="False", M121="Invalid", N121="Invalid"), "Problem", "Clean") -> Clean
A122: 1121 | B122: C121 | D122: P04 | E122: 5 | F122: 8891 | G122: 44455 | H122: Canada | I122: Cancelled | J122: =IF(G122<>(E122*F122), "Mismatch", "Ok") -> Ok | K122: =ISNUMBER(C122) -> FALSE | L122: =_xlfn.XLOOKUP( UPPER(SUBSTITUTE(TRIM(H122),".","")), A:A, B:B, UPPER(SUBSTITUTE(TRIM(H122),".","")) ) -> CANADA | M122: =IF(OR(I122="Completed", I122="Pending", I122="Cancelled"), "Valid", "Invalid") -> Valid | N122: =_xlfn.XLOOKUP(D122, Product_Master!A:A, Product_Master!A:A, "Invalid") -> P04 | O122: =IF(OR(J122="Mismatch", K122="False", M122="Invalid", N122="Invalid"), "Problem", "Clean") -> Clean
A123: 1122 | B123: C122 | C123: 2024-01-27 | D123: P07 | E123: 4 | F123: 7463 | G123: 29852 | H123: USA | I123: Cancelled | J123: =IF(G123<>(E123*F123), "Mismatch", "Ok") -> Ok | K123: =ISNUMBER(C123) -> FALSE | L123: =_xlfn.XLOOKUP( UPPER(SUBSTITUTE(TRIM(H123),".","")), A:A, B:B, UPPER(SUBSTITUTE(TRIM(H123),".","")) ) -> USA | M123: =IF(OR(I123="Completed", I123="Pending", I123="Cancelled"), "Valid", "Invalid") -> Valid | N123: =_xlfn.XLOOKUP(D123, Product_Master!A:A, Product_Master!A:A, "Invalid") -> P07 | O123: =IF(OR(J123="Mismatch", K123="False", M123="Invalid", N123="Invalid"), "Problem", "Clean") -> Clean
A124: 1123 | B124: C123 | C124: 2024-01-23 | D124: P11 | E124: 1 | F124: 1243 | G124: 1243 | H124: Canada | I124: Cancelled | J124: =IF(G124<>(E124*F124), "Mismatch", "Ok") -> Ok | K124: =ISNUMBER(C124) -> FALSE | L124: =_xlfn.XLOOKUP( UPPER(SUBSTITUTE(TRIM(H124),".","")), A:A, B:B, UPPER(SUBSTITUTE(TRIM(H124),".","")) ) -> CANADA | M124: =IF(OR(I124="Completed", I124="Pending", I124="Cancelled"), "Valid", "Invalid") -> Valid | N124: =_xlfn.XLOOKUP(D124, Product_Master!A:A, Product_Master!A:A, "Invalid") -> P11 | O124: =IF(OR(J124="Mismatch", K124="False", M124="Invalid", N124="Invalid"), "Problem", "Clean") -> Clean
A125: 1124 | B125: C124 | C125: 2024-01-16 | D125: P02 | E125: 4 | F125: 3680 | G125: 14720 | H125: India | I125: Pending | J125: =IF(G125<>(E125*F125), "Mismatch", "Ok") -> Ok | K125: =ISNUMBER(C125) -> FALSE | L125: =_xlfn.XLOOKUP( UPPER(SUBSTITUTE(TRIM(H125),".","")), A:A, B:B, UPPER(SUBSTITUTE(TRIM(H125),".","")) ) -> INDIA | M125: =IF(OR(I125="Completed", I125="Pending", I125="Cancelled"), "Valid", "Invalid") -> Valid | N125: =_xlfn.XLOOKUP(D125, Product_Master!A:A, Product_Master!A:A, "Invalid") -> P02 | O125: =IF(OR(J125="Mismatch", K125="False", M125="Invalid", N125="Invalid"), "Problem", "Clean") -> Clean
A126: 1125 | B126: C125 | C126: 2024-01-30 | D126: P03 | E126: 3 | F126: 3270 | G126: 9810 | H126: India | I126: Cancelled | J126: =IF(G126<>(E126*F126), "Mismatch", "Ok") -> Ok | K126: =ISNUMBER(C126) -> FALSE | L126: =_xlfn.XLOOKUP( UPPER(SUBSTITUTE(TRIM(H126),".","")), A:A, B:B, UPPER(SUBSTITUTE(TRIM(H126),".","")) ) -> INDIA | M126: =IF(OR(I126="Completed", I126="Pending", I126="Cancelled"), "Valid", "Invalid") -> Valid | N126: =_xlfn.XLOOKUP(D126, Product_Master!A:A, Product_Master!A:A, "Invalid") -> P03 | O126: =IF(OR(J126="Mismatch", K126="False", M126="Invalid", N126="Invalid"), "Problem", "Clean") -> Clean
A127: 1126 | B127: C126 | C127: 2024-02-13 | D127: P05 | E127: 2 | F127: 8303 | G127: 16606 | H127: Canada | I127: Completed | J127: =IF(G127<>(E127*F127), "Mismatch", "Ok") -> Ok | K127: =ISNUMBER(C127) -> FALSE | L127: =_xlfn.XLOOKUP( UPPER(SUBSTITUTE(TRIM(H127),".","")), A:A, B:B, UPPER(SUBSTITUTE(TRIM(H127),".","")) ) -> CANADA | M127: =IF(OR(I127="Completed", I127="Pending", I127="Cancelled"), "Valid", "Invalid") -> Valid | N127: =_xlfn.XLOOKUP(D127, Product_Master!A:A, Product_Master!A:A, "Invalid") -> P05 | O127: =IF(OR(J127="Mismatch", K127="False", M127="Invalid", N127="Invalid"), "Problem", "Clean") -> Clean
A128: 1127 | B128: C127 | C128: 2024-02-21 | D128: P02 | E128: 3 | F128: 2858 | G128: 8574 | H128: UK | I128: Completed | J128: =IF(G128<>(E128*F128), "Mismatch", "Ok") -> Ok | K128: =ISNUMBER(C128) -> FALSE | L128: =_xlfn.XLOOKUP( UPPER(SUBSTITUTE(TRIM(H128),".","")), A:A, B:B, UPPER(SUBSTITUTE(TRIM(H128),".","")) ) -> UK | M128: =IF(OR(I128="Completed", I128="Pending", I128="Cancelled"), "Valid", "Invalid") -> Valid | N128: =_xlfn.XLOOKUP(D128, Product_Master!A:A, Product_Master!A:A, "Invalid") -> P02 | O128: =IF(OR(J128="Mismatch", K128="False", M128="Invalid", N128="Invalid"), "Problem", "Clean") -> Clean
A129: 1128 | B129: C128 | C129: 2024-01-10 | D129: P02 | E129: 3 | F129: 3620 | G129: 10860 | H129: UK | I129: Cancelled | J129: =IF(G129<>(E129*F129), "Mismatch", "Ok") -> Ok | K129: =ISNUMBER(C129) -> FALSE | L129: =_xlfn.XLOOKUP( UPPER(SUBSTITUTE(TRIM(H129),".","")), A:A, B:B, UPPER(SUBSTITUTE(TRIM(H129),".","")) ) -> UK | M129: =IF(OR(I129="Completed", I129="Pending", I129="Cancelled"), "Valid", "Invalid") -> Valid | N129: =_xlfn.XLOOKUP(D129, Product_Master!A:A, Product_Master!A:A, "Invalid") -> P02 | O129: =IF(OR(J129="Mismatch", K129="False", M129="Invalid", N129="Invalid"), "Problem", "Clean") -> Clean
A130: 1129 | B130: C129 | C130: 2024-01-19 | D130: P11 | E130: 3 | F130: 922 | G130: 2766 | H130: UK | I130: Pending | J130: =IF(G130<>(E130*F130), "Mismatch", "Ok") -> Ok | K130: =ISNUMBER(C130) -> FALSE | L130: =_xlfn.XLOOKUP( UPPER(SUBSTITUTE(TRIM(H130),".","")), A:A, B:B, UPPER(SUBSTITUTE(TRIM(H130),".","")) ) -> UK | M130: =IF(OR(I130="Completed", I130="Pending", I130="Cancelled"), "Valid", "Invalid") -> Valid | N130: =_xlfn.XLOOKUP(D130, Product_Master!A:A, Product_Master!A:A, "Invalid") -> P11 | O130: =IF(OR(J130="Mismatch", K130="False", M130="Invalid", N130="Invalid"), "Problem", "Clean") -> Clean
A131: 1130 | B131: C130 | C131: 2024-02-28 | D131: P15 | E131: 3 | F131: 6586 | G131: 19758 | H131: India | I131: Cancelled | J131: =IF(G131<>(E131*F131), "Mismatch", "Ok") -> Ok | K131: =ISNUMBER(C131) -> FALSE | L131: =_xlfn.XLOOKUP( UPPER(SUBSTITUTE(TRIM(H131),".","")), A:A, B:B, UPPER(SUBSTITUTE(TRIM(H131),".","")) ) -> INDIA | M131: =IF(OR(I131="Completed", I131="Pending", I131="Cancelled"), "Valid", "Invalid") -> Valid | N131: =_xlfn.XLOOKUP(D131, Product_Master!A:A, Product_Master!A:A, "Invalid") -> P15 | O131: =IF(OR(J131="Mismatch", K131="False", M131="Invalid", N131="Invalid"), "Problem", "Clean") -> Clean
A132: 1131 | B132: C131 | C132: 2024-01-19 | D132: P09 | E132: 5 | F132: 7281 | G132: 36405 | H132: india | I132: Cancelled | J132: =IF(G132<>(E132*F132), "Mismatch", "Ok") -> Ok | K132: =ISNUMBER(C132) -> FALSE | L132: =_xlfn.XLOOKUP( UPPER(SUBSTITUTE(TRIM(H132),".","")), A:A, B:B, UPPER(SUBSTITUTE(TRIM(H132),".","")) ) -> INDIA | M132: =IF(OR(I132="Completed", I132="Pending", I132="Cancelled"), "Valid", "Invalid") -> Valid | N132: =_xlfn.XLOOKUP(D132, Product_Master!A:A, Product_Master!A:A, "Invalid") -> P09 | O132: =IF(OR(J132="Mismatch", K132="False", M132="Invalid", N132="Invalid"), "Problem", "Clean") -> Clean
A133: 1132 | B133: C132 | C133: 2024-01-03 | D133: P11 | E133: 5 | F133: 9219 | G133: 46095 | H133: USA | I133: Completed | J133: =IF(G133<>(E133*F133), "Mismatch", "Ok") -> Ok | K133: =ISNUMBER(C133) -> FALSE | L133: =_xlfn.XLOOKUP( UPPER(SUBSTITUTE(TRIM(H133),".","")), A:A, B:B, UPPER(SUBSTITUTE(TRIM(H133),".","")) ) -> USA | M133: =IF(OR(I133="Completed", I133="Pending", I133="Cancelled"), "Valid", "Invalid") -> Valid | N133: =_xlfn.XLOOKUP(D133, Product_Master!A:A, Product_Master!A:A, "Invalid") -> P11 | O133: =IF(OR(J133="Mismatch", K133="False", M133="Invalid", N133="Invalid"), "Problem", "Clean") -> Clean
A134: 1133 | B134: C133 | C134: 2024-02-15 | D134: P02 | E134: 3 | F134: 5114 | G134: 15342 | H134: Canada | I134: Cancelled | J134: =IF(G134<>(E134*F134), "Mismatch", "Ok") -> Ok | K134: =ISNUMBER(C134) -> FALSE | L134: =_xlfn.XLOOKUP( UPPER(SUBSTITUTE(TRIM(H134),".","")), A:A, B:B, UPPER(SUBSTITUTE(TRIM(H134),".","")) ) -> CANADA | M134: =IF(OR(I134="Completed", I134="Pending", I134="Cancelled"), "Valid", "Invalid") -> Valid | N134: =_xlfn.XLOOKUP(D134, Product_Master!A:A, Product_Master!A:A, "Invalid") -> P02 | O134: =IF(OR(J134="Mismatch", K134="False", M134="Invalid", N134="Invalid"), "Problem", "Clean") -> Clean
... A151: 1150 | B151: C150 | C151: 2024-02-23 | D151: P09 | E151: 5 | F151: 1325 | G151: 6625 | H151: Canada | I151: Cancelled | J151: =IF(G151<>(E151*F151), "Mismatch", "Ok") -> Ok | K151: =ISNUMBER(C151) -> FALSE | L151: =_xlfn.XLOOKUP( UPPER(SUBSTITUTE(TRIM(H151),".","")), A:A, B:B, UPPER(SUBSTITUTE(TRIM(H151),".","")) ) -> CANADA | M151: =IF(OR(I151="Completed", I151="Pending", I151="Cancelled"), "Valid", "Invalid") -> Valid | N151: =_xlfn.XLOOKUP(D151, Product_Master!A:A, Product_Master!A:A, "Invalid") -> P09 | O151: =IF(OR(J151="Mismatch", K151="False", M151="Invalid", N151="Invalid"), "Problem", "Clean") -> Clean
A152: 1151 | B152: C151 | C152: 2024-02-05 | D152: P10 | E152: 1 | G152: 1522 | H152: Canada | I152: Cancelled | J152: =IF(G152<>(E152*F152), "Mismatch", "Ok") -> Mismatch | K152: =ISNUMBER(C152) -> FALSE | L152: =_xlfn.XLOOKUP( UPPER(SUBSTITUTE(TRIM(H152),".","")), A:A, B:B, UPPER(SUBSTITUTE(TRIM(H152),".","")) ) -> CANADA | M152: =IF(OR(I152="Completed", I152="Pending", I152="Cancelled"), "Valid", "Invalid") -> Valid | N152: =_xlfn.XLOOKUP(D152, Product_Master!A:A, Product_Master!A:A, "Invalid") -> P10 | O152: =IF(OR(J152="Mismatch", K152="False", M152="Invalid", N152="Invalid"), "Problem", "Clean") -> Problem
A153: 1152 | B153: C152 | C153: 2024-01-25 | D153: P12 | E153: 5 | F153: 4582 | G153: 22910 | H153: Canada | I153: Completed | J153: =IF(G153<>(E153*F153), "Mismatch", "Ok") -> Ok | K153: =ISNUMBER(C153) -> FALSE | L153: =_xlfn.XLOOKUP( UPPER(SUBSTITUTE(TRIM(H153),".","")), A:A, B:B, UPPER(SUBSTITUTE(TRIM(H153),".","")) ) -> CANADA | M153: =IF(OR(I153="Completed", I153="Pending", I153="Cancelled"), "Valid", "Invalid") -> Valid | N153: =_xlfn.XLOOKUP(D153, Product_Master!A:A, Product_Master!A:A, "Invalid") -> P12 | O153: =IF(OR(J153="Mismatch", K153="False", M153="Invalid", N153="Invalid"), "Problem", "Clean") -> Clean
A154: 1153 | B154: C153 | C154: 2024-01-27 | D154: P15 | E154: 4 | F154: 2295 | G154: 9180 | H154: India | I154: Cancelled | J154: =IF(G154<>(E154*F154), "Mismatch", "Ok") -> Ok | K154: =ISNUMBER(C154) -> FALSE | L154: =_xlfn.XLOOKUP( UPPER(SUBSTITUTE(TRIM(H154),".","")), A:A, B:B, UPPER(SUBSTITUTE(TRIM(H154),".","")) ) -> INDIA | M154: =IF(OR(I154="Completed", I154="Pending", I154="Cancelled"), "Valid", "Invalid") -> Valid | N154: =_xlfn.XLOOKUP(D154, Product_Master!A:A, Product_Master!A:A, "Invalid") -> P15 | O154: =IF(OR(J154="Mismatch", K154="False", M154="Invalid", N154="Invalid"), "Problem", "Clean") -> Clean
A155: 1154 | B155: C154 | C155: 2024-02-18 | D155: P06 | E155: 2 | F155: 1407 | G155: 2814 | H155: UK | I155: Pending | J155: =IF(G155<>(E155*F155), "Mismatch", "Ok") -> Ok | K155: =ISNUMBER(C155) -> FALSE | L155: =_xlfn.XLOOKUP( UPPER(SUBSTITUTE(TRIM(H155),".","")), A:A, B:B, UPPER(SUBSTITUTE(TRIM(H155),".","")) ) -> UK | M155: =IF(OR(I155="Completed", I155="Pending", I155="Cancelled"), "Valid", "Invalid") -> Valid | N155: =_xlfn.XLOOKUP(D155, Product_Master!A:A, Product_Master!A:A, "Invalid") -> P06 | O155: =IF(OR(J155="Mismatch", K155="False", M155="Invalid", N155="Invalid"), "Problem", "Clean") -> Clean
A156: 1155 | B156: C155 | C156: 2024-01-11 | D156: P02 | E156: 5 | F156: 9213 | G156: 46065 | H156: Canada | I156: Pending | J156: =IF(G156<>(E156*F156), "Mismatch", "Ok") -> Ok | K156: =ISNUMBER(C156) -> FALSE | L156: =_xlfn.XLOOKUP( UPPER(SUBSTITUTE(TRIM(H156),".","")), A:A, B:B, UPPER(SUBSTITUTE(TRIM(H156),".","")) ) -> CANADA | M156: =IF(OR(I156="Completed", I156="Pending", I156="Cancelled"), "Valid", "Invalid") -> Valid | N156: =_xlfn.XLOOKUP(D156, Product_Master!A:A, Product_Master!A:A, "Invalid") -> P02 | O156: =IF(OR(J156="Mismatch", K156="False", M156="Invalid", N156="Invalid"), "Problem", "Clean") -> Clean
A157: 1156 | B157: C156 | C157: 2024-03-01 | D157: P01 | E157: 3 | F157: 619 | G157: 1857 | H157: India | I157: Cancelled | J157: =IF(G157<>(E157*F157), "Mismatch", "Ok") -> Ok | K157: =ISNUMBER(C157) -> FALSE | L157: =_xlfn.XLOOKUP( UPPER(SUBSTITUTE(TRIM(H157),".","")), A:A, B:B, UPPER(SUBSTITUTE(TRIM(H157),".","")) ) -> INDIA | M157: =IF(OR(I157="Completed", I157="Pending", I157="Cancelled"), "Valid", "Invalid") -> Valid | N157: =_xlfn.XLOOKUP(D157, Product_Master!A:A, Product_Master!A:A, "Invalid") -> P01 | O157: =IF(OR(J157="Mismatch", K157="False", M157="Invalid", N157="Invalid"), "Problem", "Clean") -> Clean
A158: 1157 | B158: C157 | C158: 2024-01-06 | D158: P02 | E158: 1 | F158: 3532 | G158: 3532 | H158: USA | I158: Completed | J158: =IF(G158<>(E158*F158), "Mismatch", "Ok") -> Ok | K158: =ISNUMBER(C158) -> FALSE | L158: =_xlfn.XLOOKUP( UPPER(SUBSTITUTE(TRIM(H158),".","")), A:A, B:B, UPPER(SUBSTITUTE(TRIM(H158),".","")) ) -> USA | M158: =IF(OR(I158="Completed", I158="Pending", I158="Cancelled"), "Valid", "Invalid") -> Valid | N158: =_xlfn.XLOOKUP(D158, Product_Master!A:A, Product_Master!A:A, "Invalid") -> P02 | O158: =IF(OR(J158="Mismatch", K158="False", M158="Invalid", N158="Invalid"), "Problem", "Clean") -> Clean
...

Sheet Product_Master
A1: Product_ID | B1: Product_Name
A2: P01 | B2: Product_P01
A3: P02 | B3: Product_P02
A4: P03 | B4: Product_P03
A5: P04 | B5: Product_P04
A6: P05 | B6: Product_P05
A7: P06 | B7: Product_P06
A8: P07 | B8: Product_P07
A9: P08 | B9: Product_P08
A10: P09 | B10: Product_P09
A11: P10 | B11: Product_P10
A12: P11 | B12: Product_P11
... A16: P15 | B16: Product_P15

Sheet Pivot_Tables
A3: Row Labels | B3: Count of Total_Revenue | F3: Row Labels | G3: Count of Order_ID
A4: CANADA | B4: 65 | F4: Cancelled | G4: 97
A5: INDIA | B5: 69 | F5: Completed | G5: 74
A6: UK | B6: 60 | F6: Done | G6: 1
A7: USA | B7: 56 | F7: Pending | G7: 77
A8: Grand Total | B8: 250 | F8: Processing | G8: 1
F9: Grand Total | G9: 250

Sheet QA_Findigs
A1: Executive Summary | B1: High-Level Issues Summary | G1: Recommendations
A2: Total Records Analyzed: 250 | B2: Category | C2: Records Affected | D2: Risk Level | G2: Implement automated validation controls at ingestion stage.
A3: Unique Problematic Rows: 10 | B3: Duplicate Order_ID | C3: 4 | D3: High | G3: Enforce referential integrity between transactional and master data.
A4: Overall Row-Level Error Rate: 4% | B4: Revenue Mismatch | C4: 6 | D4: High | G4: Apply mandatory field validation for critical attributes.
A5: Quantity Column Error Rate: 0.8% | B5: Invalid Product_ID | C5: 2 | D5: High | G5: Implement reconciliation logic for revenue calculation.
B6: Missing Critical Fields | C6: 3 | D6: High | G6: Standardize categorical fields using controlled reference mapping.
A7: Overall Data Quality Assessment: | B7: Invalid Date Format | C7: 249 | D7: Medium
A8: Moderate data integrity issues identified requiring validation before reporting. | B8: Negative Quantity | C8: 2 | D8: Medium
